Workbook

Sheet Estados financieros
A1: INTUIT INC. (INTU) -- SEC EDGAR (10-K), en millones de USD
A2: Las filas en celeste se calculan por formula a partir de las filas de arriba -- corregi un numero y el ratio se recalcula solo.
B4: Anio fiscal (cierre) | C4: 2016-07-31 | D4: 2017-07-31 | E4: 2018-07-31 | F4: 2019-07-31 | G4: 2020-07-31 | H4: 2021-07-31 | I4: 2022-07-31 | J4: 2023-07-31 | K4: 2024-07-31 | L4: 2025-07-31
B5: Ingresos | C5: 4694 | D5: 5177 | E5: 5964 | F5: 6784 | G5: 7679 | H5: 9633 | I5: 12726 | J5: 14368 | K5: 16285 | L5: 18831
B6: EBIT | C6: 1242 | D6: 1395 | E6: 1497 | F6: 1854 | G6: 2176 | H6: 2500 | I6: 2571 | J6: 3141 | K6: 3630 | L6: 4923
B7: Margen EBIT | C7: =IF(C5="","",C6/C5) | D7: =IF(D5="","",D6/D5) | E7: =IF(E5="","",E6/E5) | F7: =IF(F5="","",F6/F5) | G7: =IF(G5="","",G6/G5) | H7: =IF(H5="","",H6/H5) | I7: =IF(I5="","",I6/I5) | J7: =IF(J5="","",J6/J5) | ... L7: =IF(L5="","",L6/L5)
B8: Crecimiento de ingresos (a/a) | D8: =IF(OR(D5="",C5=""),"",D5/C5-1) | E8: =IF(OR(E5="",D5=""),"",E5/D5-1) | F8: =IF(OR(F5="",E5=""),"",F5/E5-1) | G8: =IF(OR(G5="",F5=""),"",G5/F5-1) | H8: =IF(OR(H5="",G5=""),"",H5/G5-1) | I8: =IF(OR(I5="",H5=""),"",I5/H5-1) | J8: =IF(OR(J5="",I5=""),"",J5/I5-1) | K8: =IF(OR(K5="",J5=""),"",K5/J5-1) | L8: =IF(OR(L5="",K5=""),"",L5/K5-1)
B11: Anio fiscal (cierre) | C11: 2021-07-31 | D11: 2022-07-31 | E11: 2023-07-31 | F11: 2024-07-31 | G11: 2025-07-31
B12: Gasto en intereses | C12: 29 | D12: 81 | E12: 248 | F12: 242 | G12: 247
B13: D&A
B14: CapEx | C14: 53 | D14: 157 | E14: 210 | F14: 191 | G14: 84
B15: Gasto en I+D | C15: 1678 | D15: 2347 | E15: 2539 | F15: 2754 | G15: 2928
B16: Impuesto a las ganancias | C16: 494 | D16: 476 | E16: 605 | F16: 587 | G16: 965
B17: Resultado antes de impuestos | C17: 2556 | D17: 2542 | E17: 2989 | F17: 3550 | G17: 4834
B18: Dividendo por accion (USD) | C18: 2.36 | D18: 2.72 | E18: 3.12 | F18: 3.6 | G18: 4.16
B19: Emision de deuda
B20: Repago de deuda | C20: 338 | D20: 0 | E20: 1009 | F20: 4200 | G20: 500
B21: Acciones en circulacion (cierre, M) | C21: 273.235 | D21: 281.932 | E21: 280.421 | F21: 280.268 | G21: 279.129
B23: Interes / EBIT | C23: =IF(OR(C12="",H6=""),"",C12/H6) | D23: =IF(OR(D12="",I6=""),"",D12/I6) | E23: =IF(OR(E12="",J6=""),"",E12/J6) | F23: =IF(OR(F12="",K6=""),"",F12/K6) | G23: =IF(OR(G12="",L6=""),"",G12/L6)
B24: D&A / Ingresos | C24: =IF(OR(C13="",H5=""),"",C13/H5) | D24: =IF(OR(D13="",I5=""),"",D13/I5) | E24: =IF(OR(E13="",J5=""),"",E13/J5) | F24: =IF(OR(F13="",K5=""),"",F13/K5) | G24: =IF(OR(G13="",L5=""),"",G13/L5)
B25: CapEx / Ingresos | C25: =IF(OR(C14="",H5=""),"",C14/H5) | D25: =IF(OR(D14="",I5=""),"",D14/I5) | E25: =IF(OR(E14="",J5=""),"",E14/J5) | F25: =IF(OR(F14="",K5=""),"",F14/K5) | G25: =IF(OR(G14="",L5=""),"",G14/L5)
B26: Tasa impositiva efectiva | C26: =IF(OR(C16="",C17=""),"",C16/C17) | D26: =IF(OR(D16="",D17=""),"",D16/D17) | E26: =IF(OR(E16="",E17=""),"",E16/E17) | F26: =IF(OR(F16="",F17=""),"",F16/F17) | G26: =IF(OR(G16="",G17=""),"",G16/G17)
B27: Endeudamiento neto / Ingresos | C27: =IF(OR(C19="",C20="",H5=""),"",(C19-C20)/H5) | D27: =IF(OR(D19="",D20="",I5=""),"",(D19-D20)/I5) | E27: =IF(OR(E19="",E20="",J5=""),"",(E19-E20)/J5) | F27: =IF(OR(F19="",F20="",K5=""),"",(F19-F20)/K5) | G27: =IF(OR(G19="",G20="",L5=""),"",(G19-G20)/L5)
B28: Crecimiento de dividendos (a/a) | D28: =IF(OR(D18="",C18=0,C18=""),"",D18/C18-1) | E28: =IF(OR(E18="",D18=0,D18=""),"",E18/D18-1) | F28: =IF(OR(F18="",E18=0,E18=""),"",F18/E18-1) | G28: =IF(OR(G18="",F18=0,F18=""),"",G18/F18-1)
B29: Crecimiento de acciones (a/a) | D29: =IF(OR(D21="",C21=""),"",D21/C21-1) | E29: =IF(OR(E21="",D21=""),"",E21/D21-1) | F29: =IF(OR(F21="",E21=""),"",F21/E21-1) | G29: =IF(OR(G21="",F21=""),"",G21/F21-1)
B32: LTM (suma de 4 trimestres consecutivos; si faltan o hay un hueco, se usa el ultimo 10-K)
B33: (columnas C-F = ultimos 4 trimestres; columna H = suma = LTM)
B34: Ingresos (trimestres)
B35: EBIT (trimestres)
B36: Intereses (trimestres)
B39: Balance -- ultimo 10-K cerrado vs. mas reciente (10-Q/10-K), en millones
C40: Ultimo 10-K | D40: Mas reciente
B41: Valor libro del equity | C41: 19710 | D41: 20629
B42: Deuda de largo plazo | C42: 5973 | D42: 5412
B43: Deuda corriente | C43: 0 | D43: 750
B44: Deuda total (LP + corriente) | C44: =C42+C43 | D44: =D42+D43
B45: Caja | C45: 2884 | D45: 4681
B46: Interes minoritario | C46: 0 | D46: 0
B47: NOL acumulado | C47: 0 | D47: 0
B48: Acciones en circulacion (M) | C48: 279.129 | D48: 279.129

Sheet Inputs dashboard
A1: Campo (mismo nombre que en el dashboard) | B1: Valor
A2: Celeste = calculado por formula desde 'Estados financieros'. Amarillo = SEC EDGAR no lo tiene, completalo vos.
A3: ticker | B3: INTU
A4: company_name | B4: INTUIT INC.
A5: country_of_incorporation | B5: United States
A6: industry_us | B6: Services-Prepackaged Software
A7: industry_global | B7: Services-Prepackaged Software
A8: current_price | B8: 650
A9: revenue_ltm | B9: ='Estados financieros'!L5
A10: revenue_prior_10k | B10: ='Estados financieros'!L5
A11: ebit_ltm | B11: ='Estados financieros'!L6
A12: ebit_prior_10k | B12: ='Estados financieros'!L6
A13: interest_expense_ltm | B13: ='Estados financieros'!G12
A14: interest_expense_prior_10k | B14: ='Estados financieros'!G12
A15: book_value_equity_ltm | B15: ='Estados financieros'!D41
A16: book_value_equity_prior_10k | B16: ='Estados financieros'!C41
A17: book_value_debt_ltm | B17: ='Estados financieros'!D44
A18: book_value_debt_prior_10k | B18: ='Estados financieros'!C44
A19: cash_ltm | B19: ='Estados financieros'!D45
A20: cash_prior_10k | B20: ='Estados financieros'!C45
A21: minority_interests | B21: ='Estados financieros'!D46
A22: shares_outstanding | B22: ='Estados financieros'!D48
A23: nol_carryforward | B23: ='Estados financieros'!D47
A24: effective_tax_rate | B24: =AVERAGE('Estados financieros'!C26:G26)
A25: dividend_per_share_ltm | B25: ='Estados financieros'!G18
A26: ebit_margin_ltm | B26: ='Estados financieros'!L6/'Estados financieros'!L5
A27: ebit_margin_avg_3y | B27: =AVERAGE('Estados financieros'!J7:L7)
A28: ebit_margin_avg_5y | B28: =AVERAGE('Estados financieros'!H7:L7)
A29: ebit_margin_avg_10y | B29: =AVERAGE('Estados financieros'!C7:L7)
A30: revenue_growth_next_year | B30: =IF(OR('Estados financieros'!I5="",'Estados financieros'!I5<=0),0,('Estados financieros'!L5/'Estados financieros'!I5)^(1/3)-1)
A31: revenue_growth_years_2_to_5 | B31: =IF(OR('Estados financieros'!I5="",'Estados financieros'!I5<=0),0,('Estados financieros'!L5/'Estados financieros'!I5)^(1/3)-1)
A32: riskfree_rate | B32: 0.045
A33: initial_cost_of_capital | B33: 0.09
A34: hist_interest_pct_of_ebit | B34: =AVERAGE('Estados financieros'!C23:G23)
A35: hist_da_pct_of_revenue | B35: =AVERAGE('Estados financieros'!C24:G24)
A36: hist_capex_pct_of_revenue | B36: =AVERAGE('Estados financieros'!C25:G25)
A37: hist_net_borrowing_pct_of_revenue | B37: =AVERAGE('Estados financieros'!C27:G27)
A38: hist_shares_growth_rate | B38: =IF(OR('Estados financieros'!D21="",'Estados financieros'!D21<=0),0,('Estados financieros'!G21/'Estados financieros'!D21)^(1/3)-1)
A39: hist_dividend_growth_rate | B39: =IF(OR('Estados financieros'!D18="",'Estados financieros'!D18<=0),0,('Estados financieros'!G18/'Estados financieros'!D18)^(1/3)-1)
A40: capitalize_rd | B40: Yes
...
